<?xml version="1.0" ?>
<sdf version="1.6">
  <model name="three_wheel_robot">
    <static>false</static>
    <link name="base_link">
      <pose>0 0 0.1 0 0 0</pose>
      <collision name="collision">
        <geometry>
          <box>
            <size>0.5 0.5 0.1</size>
          </box>
        </geometry>
      </collision>
      <visual name="visual">
        <geometry>
          <box>
            <size>0.5 0.5 0.1</size>
          </box>
        </geometry>
      </visual>
      <sensor name="proximity_sensor" type="contact">
        <pose>0 0 0.1 0 0 0</pose>
        <contact>
          <topic>~/proximity_sensor</topic>
        </contact>
      </sensor>
      <sensor name="gyroscope" type="imu">
        <pose>0 0 0 0 0 0</pose>
        <imu>
          <topic>~/gyroscope</topic>
        </imu>
      </sensor>
      <sensor name="camera" type="camera">
        <pose>0.2 0 0.1 0 0 0</pose>
        <camera>
          <horizontal_fov>1.047</horizontal_fov>
          <image>
            <width>640</width>
            <height>480</height>
          </image>
          <clip>
            <near>0.1</near>
            <far>100</far>
          </clip>
        </camera>
      </sensor>
    </link>
    <link name="wheel_left">
      <pose>-0.2 0.2 0 0 0 0</pose>
      <collision name="collision">
        <geometry>
          <cylinder>
            <radius>0.1</radius>
            <length>0.05</length>
          </cylinder>
        </geometry>
      </collision>
      <visual name="visual">
        <geometry>
          <cylinder>
            <radius>0.1</radius>
            <length>0.05</length>
          </cylinder>
        </geometry>
      </visual>
    </link>
    <link name="wheel_right">
      <pose>0.2 0.2 0 0 0 0</pose>
      <collision name="collision">
        <geometry>
          <cylinder>
            <radius>0.1</radius>
            <length>0.05</length>
          </cylinder>
        </geometry>
      </collision>
      <visual name="visual">
        <geometry>
          <cylinder>
            <radius>0.1</radius>
            <length>0.05</length>
          </cylinder>
        </geometry>
      </visual>
    </link>
    <link name="wheel_rear">
      <pose>0 0.2 0 0 0 0</pose>
      <collision name="collision">
        <geometry>
          <cylinder>
            <radius>0.1</radius>
            <length>0.05</length>
          </cylinder>
        </geometry>
      </collision>
      <visual name="visual">
        <geometry>
          <cylinder>
            <radius>0.1</radius>
            <length>0.05</length>
          </cylinder>
        </geometry>
      </visual>
    </link>
    <joint name="left_wheel_hinge" type="revolute">
      <parent>base_link</parent>
      <child>wheel_left</child>
      <axis>
        <xyz>0 1 0</xyz>
        <limit>
          <lower>-1.0</lower>
          <upper>1.0</upper>
        </limit>
      </axis>
    </joint>
    <joint name="right_wheel_hinge" type="revolute">
      <parent>base_link</parent>
      <child>wheel_right</child>
      <axis>
        <xyz>0 1 0</xyz>
        <limit>
          <lower>-1.0</lower>
          <upper>1.0</upper>
        </limit>
      </axis>
    </joint>
    <joint name="rear_wheel_hinge" type="revolute">
      <parent>base_link</parent>
      <child>wheel_rear</child>
      <axis>
        <xyz>0 1 0</xyz>
        <limit>
          <lower>-1.0</lower>
          <upper>1.0</upper>
        </limit>
      </axis>
    </joint>
  </model>
</sdf>
